Workbook

Sheet Funda
B2: Accounting Concepts (fundamental assumptions)
B4: 1. Business Entity Concept – Business is separate from its owners
B6: 2. Going Concern Concept – Business will continue in the foreseeable future
B8: 3. Money Measurement Concept – Only transactions measurable in money are recorded
B10: 4. Accounting Period Concept – Life of business is divided into time periods
B12: 5. Historical Cost Concept – Assets are recorded at acquisition cost
B14: 6. Accrual Concept – Income and expenses are recognized when incurred, not when cash is received/paid
B16: 7. Matching Concept – Expenses are matched with related revenues
B18: 8. Realisation (Revenue Recognition) Concept – Revenue is recognized when earned and realized
B20: 9. Dual Aspect Concept – Every transaction has two effects (debit and credit)
B24: Accounting Conventions (practical guidelines)
B26: 1. Convention of Consistency – Same accounting methods used over time
... B32: 4. Convention of Materiality – Only material items need detailed disclosure

Sheet Titan BS
B3: Standalone balance sheet as at 31st March 2025
B4: Particulars | C4: 2025 | D4: 2024 | I4: Formula | J4: 45717 | K4: 45352 | L4: 45717 | M4: 45352
B5: ASSETS | H5: What is the Current Ratio of Titan ltd? | I5: CA/CL | L5: =C31/C57 -> 1.4065142 | M5: =D31/D57 -> 1.6983236 | O5: Indicates the ability to meet currently maturing obligations
B6: (1) Non-current assets | H6: Quick Assest | I6: CA-Inventories | L6: =C31-C22 -> 5927 | M6: =D31-D22 -> 5819
B7: (a) Property, plant and equipment | C7: 1474 | D7: 1380 | H7: The Quick Ratio is closest to: | I7: (CA-Inventories)/CL | L7: =L6/C57 -> 0.27382767 | M7: =M6/D57 -> 0.4354887 | O7: Indicates the ability to meet immediately maturing obligations
B8: (b) Capital work-in-progress (Projects under construction) | C8: 86 | D8: 81
B9: (c) Right-of-use assets | C9: 1449 | D9: 1225 | H9: The Cash Ratio is: | I9: Cash+Bank/CL | L9: =(C26+C27)/C57 -> 0.052298452 | M9: =(D26+D27)/D57 -> 0.060245472 | O9: Indicates the proportion of current obligations which can be met with cash or cash equivalents
B10: (d) Investment property | C10: 1 | D10: 1 | H10: Net Working Capital | I10: CA-CL | L10: =C31-C57 -> 8799 | M10: =D31-D57 -> 9331
B11: (e) Intangible assets (trade marks) | C11: 95 | D11: 85 | H11: Inventory to Net Working Capital is: | I11: Inventory/NWC | L11: =C22/L10 -> 2.7863394 | M11: =D22/M10 -> 1.8083807 | O11: Indicates the proportion of inventory in Working Capital
B12: (f) Intangible assets under development | C12: 8 | D12: 6
B13: (g) Financial assets | H13: The Debt-to-Equity Ratio is: | I13: Long term Debt/Total Equity | L13: =C44/C37 -> 0.15579085 | M13: =D44/D37 -> 0.34882756 | O13: Indicates the proportion of funds provided by lenders/ creditors versus the funds by owners
B14: (i) Investments | C14: 6386 | D14: 6178 | H14: Total Debt | I14: NCL+CL | L14: =C57+C44 -> 24264 | M14: =D57+D44 -> 18405
B15: (ii) long term Loans and advances | C15: 59 | D15: 53 | H15: The Debt-to-Asset Ratio is: | I15: Total Debt/Total assets | L15: =L14/C32 -> 0.59072428 | M15: =M14/D32 -> 0.56006938 | O15: Indicates the proportion of funds provided by lenders/ creditors to Total Assets
B16: (iii) Other long trem financial assets | C16: 739 | D16: 680
B17: (h) Deferred tax assets (net) | C17: 125 | D17: 153 | H17: ROCE (%) is approximately: | I17: EBIT/Capital Employed | L17: =M18/L18*100 -> 27.009779 | O17: Indicates the return earned on Capital Employed
B18: (i) Income tax assets (net) | C18: 85 | D18: 199 | H18: Capital Employed & EBIT | I18: Total Equity+NCL | L18: =C37+C44 -> 19430 | M18: 5248 | N18: EBIT
B19: (j) Other non-current assets | C19: 124 | D19: 128 | H19: ROTA (%) is: | I19: PAT/TA | L19: =L20/C32*100 -> 8.119294 | M19: =M20/D32*100 -> 10.784493 | O19: Indicates the profit earned on Assets used
C20: 10631 | D20: 10169 | H20: PAT | L20: 3335 | M20: 3544
B21: (2) Current assets | H21: ROE (%) is: | I21: PAT/TE | L21: =L20/C37 -> 0.19838201 | M21: =M20/D37*100 -> 24.514076 | O21: Indicates the return earned on Owners Funds
B22: (a) Inventories | C22: 24517 | D22: 16874 | H22: Total Rev | L22: 55335
B23: (b) Financial assets | H23: Asset Turnover Ratio is closest to: | I23: Total Revenue/TA | L23: =L22/C32 -> 1.3471698 | O23: To assess the efficiency in utilization of Total Assets for generating revenue
B24: (i) Investments (quoted market value) | C24: 1337 | D24: 1635 | H24: OP REVENUE | L24: 54842 | M24: 47114
B25: (ii) Trade receivables | C25: 984 | D25: 937 | H25: Fixed Asset Turnover Ratio is: | I25: OP Rev / FA | L25: =L24/P32 -> 17.61709 | M25: =M24/P32 -> 15.134597 | O25: To assess the efficiency in utilization of Fixed Assets for generating revenue
B26: (iii) Cash and cash equivalents | C26: 243 | D26: 272 | H26: NWC | I26: CA-CL | L26: =C31-C57 -> 8799 | M26: =D31-D57 -> 9331 | N26: =(L26+M26)/2 -> 9065
B27: (iv) Bank balances other than (iii) above | C27: 889 | D27: 533 | H27: Working Capital Turnover Ratio is: | I27: OP Rev /NWC | L27: =L24/L26 -> 6.2327537 | M27: =M24/M26 -> 5.0491909 | O27: To assess the efficiency in utilization of Working Capital
B28: (v) Loans and advances less than 9 months | C28: 340 | D28: 277
B29: (vi) Other financial assets less than 9 months | C29: 509 | D29: 875 | H29: Accounts Receivable Turnover Ratio is: | I29: OP Rev / Trade Recv | L29: =L24/C25 -> 55.73374 | M29: =M24/D25 -> 50.28175
B30: (c) Other current assets | C30: 1625 | D30: 1290
C31: 30444 | D31: 22693 | H31: Average Collection Period (days) is approximately: | I31: 365/Acct Recv turnover | L31: =365/L29 -> 6.5489953 | M31: =365/M29 -> 7.259095 | O31: To assess the efficiency in the management/collection of Accounts receivable
B32: TOTAL ASSETS | C32: 41075 | D32: 32862 | I32: Fixed assets | L32: =C7+C8+C9+C10+C11+C12 -> 3113 | O32: Fixed assets | P32: =C7+C8+C9+C10+C11+C12 -> 3113
B33: EQUITY AND LIABILITIES | H33: Inventory Turnover | I33: COGS/Inventory | L33: =L34/C22 -> 1.7840682 | M33: =M34/D22 -> 2.1892853 | O33: To assess the efficiency in the management of Inventory
B34: Equity | I34: COGS | L34: 43740 | M34: 36942
B35: (a) Equity share capital | C35: 89 | D35: 89 | H35: Inventory Days | I35: 365/inventory turnover | L35: =365/L33 -> 204.58859 | M35: =365/M33 -> 166.72108 | O35: To assess the efficiency in the management of Inventory
B36: (b) Other equity | C36: 16722 | D36: 14368 | H36: Trade Payable Turnover | I36: COGS/Trade Payables | L36: =L34/(C51+C52) -> 29.714674 | M36: =M34/(D51+D52) -> 39.174973 | O36: indicates faster and more frequent payment to suppliers
B37: TOTAL EQUITY | C37: 16811 | D37: 14457 | H37: Trade Payable Days | I37: 365/ Payable turnover | L37: =365/L36 -> 12.283493 | M37: =365/M36 -> 9.3171729 | O37: indicates that the firm takes longer to pay suppliers, conserving cash but potentially affecting supplier relationships
B38: Liabilities
B39: (1) Non-current liabilities | H39: Market capitalisation on 2025 (in Cr.) | I39: 317108
B40: (a) Financial liabilities | H40: Price | I40: =I39/I41 -> 3563.0112
B41: (i) Long term Borrowings | C41: 420 | D41: 3139 | H41: Total share outstanding (in Cr.) | I41: 89 | M41: 89
B42: (ii) Long term Lease liabilities | C42: 1943 | D42: 1666 | H42: EPS | I42: PAT/Total share Outstanding | L42: =L20/I41 -> 37.47191
...

Sheet Titan PL
B1: Standalone statement of profit and loss for the year ended 31st March 2025
B2: Particulars | C2: 2025 | D2: 2024
B3: Sales Gross | C3: 55872 | D3: 49641
B4: Sales Return | C4: 1030 | D4: 2527 | J4: Profitability Margin | K4: Formula | L4: 45717 | M4: 45352
B5: I. Revenue from operations | C5: 54842 | D5: 47114 | F5: =C3-C4 -> 54842 | G5: =D3-D4 -> 47114 | J5: EBITDA Margin (%) for Mar-25 is: | K5: EBITDA/Total Operating revenue*100 | L5: =(C18+C14+C13)/C5*100 -> 10.548485 | M5: =(D18+D14+D13)/D5*100 -> 11.745978 | N5: Indicates the EBITDA as percentage of Total Operating revenue
B6: II. Other income | C6: 493 | D6: 510 | J6: EBIT Margin (%) for Mar-25 is: | K6: EBIT/Total Operating revenue*100 | L6: =F18/C5*100 -> 9.5693082 | M6: =G18/D5 -> 0.10797215 | N6: Indicates the EBIT as percentage of Total Operating revenue
B7: III. Total income (I +II) | C7: 55335 | D7: 47624 | J7: Net Profit Margin (%) for Mar-24 is: | K7: Net profit/Total Operating revenue*100 | L7: =C24/C7*100 -> 6.0269269 | M7: =D24/D7*100 -> 7.4416261 | N7: Indicates the Profit After Tax (PAT) as percentage of Total Operating revenue
B8: IV. Expenses: | J8: % Change in Other Income from Mar-24 to Mar-25 is: | K8: % Change in/Total Operating revenue*100 | L8: =(C6-D6)/D6*100 -> -3.3333333 | N8: Decreases
B9: Cost of raw materials and components consumed | C9: 43905 | D9: 33556 | J9: Interest Coverage Ratio for Mar-25 is: | K9: Interest coverage/Total Operating revenue*100 | L9: =F18/C13 -> 6.8422425 | M9: =G18/D13 -> 10.597917 | N9: Indicates the ability of the company to meet its interest obligations
B10: Purchase of stock-in-trade | C10: 6372 | D10: 5535
B11: Changes in inventories of finished goods, stock-in-trade and work-in progress | C11: -6537 | D11: -2149 | E11: =SUM(C9:C11) -> 43740 | F11: =SUM(D9:D11) -> 36942 | G11: COGS | H11: Op stock+ Purchase- Closting
B12: Employee benefits expense | C12: 1717 | D12: 1503
B13: Finance costs | C13: 767 | D13: 480
B14: Depreciation and amortisation expense | C14: 537 | D14: 447
B15: Other expenses | C15: 4093 | D15: 3645
B16: Total expenses | C16: 50854 | D16: 43017
B17: expectional expenses
B18: V. Profit before tax (III - IV) | C18: 4481 | D18: 4607 | E18: EBIT | F18: =C18+C13 -> 5248 | G18: =D18+D13 -> 5087
B20: VI. Tax expense:
B21: Current tax | C21: 1117 | D21: 1072
B22: Deferred tax | C22: 29 | D22: -9
B23: Total tax expense | C23: 1146 | D23: 1063
B24: VII. Profit for the year (V-VI) | C24: 3335 | D24: 3544 | E24: PAT
B25: VIII. Other comprehensive income
B26: Items that will not be reclassified to the statement of profit and loss
B27: - Remeasurement of employee defined benefit plans | C27: -25 | D27: -4
B28: - Income-tax on above | C28: 6 | D28: 1
B29: Total other comprehensive loss | C29: -19 | D29: -3
B30: IX. Total comprehensive income (VII+VIII) | C30: 3316 | D30: 3541
B31: X. Earnings per equity share of ` 1:
B32: {based on profit for the year (V)}
B33: Basic | C33: 37.6 | D33: 39.94
B34: Diluted | C34: 37.58 | D34: 39.92
B37: Dividend Paid | C37: 1276 | D37: 1152

Sheet Answer key
A1: MBA | E1: Btech
A2: Questions | B2: Answer Key | E2: Questions | F2: Answer Key
A3: 1 | B3: D | E3: 1 | F3: D
A4: 2 | B4: C | E4: 2 | F4: C
A5: 3 | B5: A | E5: 3 | F5: A
A6: 4 | B6: A | E6: 4 | F6: A
A7: 5 | B7: C | E7: 5 | F7: C
A8: 6 | B8: B | E8: 6 | F8: E
A9: 7 | B9: C | E9: 7 | F9: A
A10: 8 | B10: B | E10: 8 | F10: E
A11: 9 | B11: B | E11: 9 | F11: A
A12: 10 | B12: E | E12: 10 | F12: E
A13: 11 | B13: A | E13: 11 | F13: E
A14: 12 | B14: E | E14: 12 | F14: B
... A37: 35 | B37: B | E37: 35 | F37: C
A38: 36 | B38: C
A39: 37 | B39: C
A40: 38 | B40: B
A41: 39 | B41: E
A42: 40 | B42: E
A43: 41 | B43: A
A44: 42 | B44: E
A45: 43 | B45: B
A46: 44 | B46: C
A47: 45 | B47: C
A48: 46 | B48: A
A49: 47 | B49: A
... A52: 50 | B52: A

Sheet Avenue Supmrt_PL
A1: Profit & Loss Avenue Supermarts Ltd(Curr. in )
A2: Year | B2: 202503 | C2: 202403
A3: INCOME :
A4: Sales Turnover | B4: 65382.87 | C4: 55894.17
A5: Excise Duty | B5: 6024.82 | C5: 5105.34
A6: Net Sales | B6: 59358.05 | C6: 50788.83
A7: Other Income | B7: 124.31 | C7: 146.45
A8: Stock Adjustments | B8: 1117.06 | C8: 683.77
A9: Total Income | B9: 60599.42 | C9: 51619.05
A10: EXPENDITURE :
A11: Raw Materials (COGS) | B11: 51668.76 | C11: 43958.31
A12: Power & Fuel Cost | B12: 447.75 | C12: 376.59
A13: Employee Cost | B13: 1165.9 | C13: 906.12
A14: Other Manufacturing Expenses | B14: 1751.85 | C14: 1323.43
A15: Selling and Administration Expenses | B15: 314.05 | C15: 276.13
A16: Miscellaneous Expenses | B16: 639.47 | C16: 528.25
A17: Less: Pre-operative Expenses Capitalised | B17: 0 | C17: 0
A18: Total Expenditure | B18: 55987.78 | C18: 47368.83
A19: Operating Profit (EBIT) | B19: 4611.64 | C19: 4250.22
A20: Interest | B20: 69.45 | C20: 58.13
A21: Gross Profit | B21: 4542.19 | C21: 4192.09
A22: Depreciation | B22: 869.52 | C22: 730.76
... A49: Dividend Per Share Adj.(Rs) | B49: 0 | C49: 0
A50: Disclaimer:-

Sheet Avenue Supmrt_BS
A1: Profit & Loss Avenue Supermarts Ltd(Curr. in )
A2: Year | B2: 202503 | C2: 202403
A3: Non-Current Assets: | F3: Liquidity Ratios | G3: Formula | H3: 2025 | I3: 2024
A4: Fixed Assets | B4: 17298.16 | C4: 14342.13
A5: Property, Plant and Equipment | B5: 14349.83 | C5: 11759.19 | F5: Current Ratio | G5: CA/CL | H5: =B40/B85 -> 2.889574 | I5: =C40/C85 -> 3.1336995
A6: Capital Work in Progress | B6: 1099.35 | C6: 935.22 | F6: Quick Ratio | G6: (CA-Inventory)/CL | H6: =(B40-B27)/B85 -> 0.60928233 | I6: =(C40-C27)/C85 -> 1.1493477
A7: Right-of-Use Assets | B7: 1741.73 | C7: 1539.1 | F7: Cash Ratio | G7: (Cash + Bank)/CL | H7: =(B32+B33)/B85 -> 0.16192319 | I7: =(C32+C33)/C85 -> 0.32245319
A8: Intangible Assets | B8: 107.25 | C8: 108.62
A9: Intangible Assets under Development | B9: 0 | C9: 0
A10: Fixed Assets Held For Sale | B10: 0 | C10: 0 | F10: Solvency Ratios | H10: 2025 | I10: 2024
A11: Lease Adjustment | B11: 0 | C11: 0
A12: Biological Assets other than Bearer Plants | B12: 0 | C12: 0 | F12: Debt to Equity Ratio | G12: NCL/ TE | H12: =B74/B64 -> 0.031802844 | I12: =C74/C64 -> 0.02678028
A13: Non-current Investments | F13: Total Debt to Assets Ratio | G13: (TA-TE)/TA | H13: =(B46-B64)/B46 -> 0.11897843 | I13: =(C46-C64)/C46 -> 0.11710047
A14: Investment Properties | B14: 7.65 | C14: 8.09 | F14: Equity Multiplier | G14: TA/TE | H14: =B46/B64 -> 1.135046 | I14: =C46/C64 -> 1.1326317
A15: Investments in Subsidiaries, Associates and Joint venture | B15: 0 | C15: 0
A16: Financial Assets : | F16: Turnover/Efficiency Ratios | H16: 2025 | I16: 2024
A17: Investments of Life Insurance Business | B17: 0 | C17: 0
A18: Investments - Long-term | B18: 2.01 | C18: 0.01 | F18: Inventory Turnover | G18: COGS/Inventories | H18: ='Avenue Supmrt_PL'!B11/'Avenue Supmrt_BS'!B27 -> 10.242857 | I18: ='Avenue Supmrt_PL'!C11/'Avenue Supmrt_BS'!C27 -> 11.192982
A19: Loans - Long - Term | B19: 0 | C19: 0 | F19: Receivables Turnover | G19: Sales/Trade Recv | H19: ='Avenue Supmrt_PL'!B6/'Avenue Supmrt_BS'!B31 -> 385.9682 | I19: ='Avenue Supmrt_PL'!C9/'Avenue Supmrt_BS'!C31 -> 310.26657
A20: Others Financial Assets - Long-term | B20: 168.12 | C20: 234.76 | F20: Asset Turnover | G20: Sales/TA | H20: ='Avenue Supmrt_PL'!B6/'Avenue Supmrt_BS'!B46 -> 2.4406802 | I20: ='Avenue Supmrt_PL'!C6/'Avenue Supmrt_BS'!C46 -> 2.3982788
A21: Non Current Tax Assets - Long - Term | B21: 18.19 | C21: 17.56 | F21: Payables Turnover | G21: COGS/ Trade Payable | H21: ='Avenue Supmrt_PL'!B11/B78 -> 48.252034 | I21: ='Avenue Supmrt_PL'!C11/C78 -> 44.636336
A22: Insurance Related Assets | B22: 0 | C22: 0
A23: Other Non-current Assets | B23: 426.45 | C23: 367.9 | F23: No of Days of Inventory | G23: 365/inventory turnover | H23: =365/H18 -> 35.634589 | I23: =365/I18 -> 32.609719
A24: Deferred Tax Assets (Net) | B24: 7.51 | C24: 4.72 | F24: No of Days of Receivables | G24: 365/Recv turnover | H24: =365/H19 -> 0.94567375 | I24: =365/I19 -> 1.1764077
A25: Total Reported Non-current Assets | B25: 17928.09 | C25: 14975.17 | F25: No of Days of Payables | G25: 365/Payable turnover | H25: =365/H21 -> 7.564448 | I25: =365/I21 -> 8.1771945
A26: Current Assets:
A27: Inventories | B27: 5044.37 | C27: 3927.31 | F27: Operating Cycle | G27: Inventory days+ Recv Days | H27: =H23+H24 -> 36.580263 | I27: =I23+I24 -> 33.786127
A28: Biological Assets other than Bearer Plants | B28: 0 | C28: 0 | F28: Cash Cycle | G28: Inv. Days+ Recv Days - Payable days | H28: =H23+H24-H25 -> 29.015815 | I28: =I23+I24-I25 -> 25.608933
A29: Financial Assets :
A30: Current Investments | B30: 1.25 | C30: 106.66
A31: Trade Receivables | B31: 153.79 | C31: 166.37 | F31: Coverage Ratios | H31: 2025 | I31: 2024
A32: Cash and Cash Equivalents | B32: 355.48 | C32: 337.12
A33: Bank Balances Other Than Cash and Cash Equivalents | B33: 2.72 | C33: 301.06 | F33: Interest Coverage | G33: Op. Profit/Interest Exp. | H33: ='Avenue Supmrt_PL'!B19/'Avenue Supmrt_PL'!B20 -> 66.402304 | I33: ='Avenue Supmrt_PL'!C19/'Avenue Supmrt_PL'!C20 -> 73.115775
A34: Loans - Short-term | B34: 0 | C34: 0 | F34: Cash Coverage | G34: (Op.Profit+ Dep)/Interest Exp | H34: =('Avenue Supmrt_PL'!B19+'Avenue Supmrt_PL'!B22)/'Avenue Supmrt_PL'!B20 -> 78.92239 | I34: =('Avenue Supmrt_PL'!C19+'Avenue Supmrt_PL'!C22)/'Avenue Supmrt_PL'!C20 -> 85.686909
A35: Others Financial Assets - Short-term | B35: 528.36 | C35: 1128.49
A36: Current Tax Assets - Short-term | B36: 0 | C36: 0
A37: Insurance Related Assets | B37: 0 | C37: 0
A38: Other Current Assets | B38: 306.23 | C38: 235.02 | F38: Profiatbility Ratios | H38: 2025 | I38: 2024
A39: Assets Classified as Held for Sale | B39: 0 | C39: 0
A40: Total Current Assets | B40: 6392.2 | C40: 6202.03 | F40: Net Profit Margin | G40: Net profit/Sales | H40: ='Avenue Supmrt_PL'!B33/'Avenue Supmrt_PL'!B6 -> 0.045443036 | I40: ='Avenue Supmrt_PL'!C33/'Avenue Supmrt_PL'!C6 -> 0.04957153
...

Sheet Change in Inv.
C2: Company A | I2: Company B
D3: 2025 | E3: 2024 | F3: 2023 | I3: 2025 | J3: 2024 | K3: 2023
C4: Opening Stock | D4: 2341 | E4: 1954 | F4: 1736 | I4: 589 | J4: 1198 | K4: 1476
C5: Purchase | D5: 3457 | E5: 4381 | F5: 5250 | I5: 2438 | J5: 3570 | K5: 4563
C6: Closing Stock | D6: 3163 | E6: 2341 | F6: 1954 | I6: 410 | J6: 589 | K6: 1198
B8: COGS | C8: Opening stock +Purchase-Closing stock | D8: =D4+D5-D6 -> 2635 | E8: =E4+E5-E6 -> 3994 | F8: =F4+F5-F6 -> 5032 | I8: =I4+I5-I6 -> 2617 | J8: =J4+J5-J6 -> 4179 | K8: =K4+K5-K6 -> 4841
B10: AS per P&L | C10: In Profit and Loss Statement
C11: Purchase | D11: 3457 | E11: =E5 -> 4381 | F11: =F5 -> 5250 | I11: =I5 -> 2438 | J11: =J5 -> 3570 | K11: =K5 -> 4563
C12: Change in Inventory | D12: =D4-D6 -> -822 | E12: =E4-E6 -> -387 | F12: =F4-F6 -> -218 | I12: =I4-I6 -> 179 | J12: =J4-J6 -> 609 | K12: =K4-K6 -> 278
C13: COGS | D13: =D11+D12 -> 2635 | E13: =E11+E12 -> 3994 | F13: =F11+F12 -> 5032 | I13: =I11+I12 -> 2617 | J13: =J11+J12 -> 4179 | K13: =K11+K12 -> 4841
A15: Key Learnings (When Closing Inventory is higher)
B16: The firm produced or purchased more than it sold
B17: Some cost is carried forward as asset (inventory)
B18: Therefore, expense recognized this year is lower
B19: Profit increases
C22: Situation | D22: Impact
C23: Higher Closing Inventory | D23: Lower COGS
C24: Lower COGS | D24: Higher Profit
C25: Inventory Increase | D25: Cash locked in stock

Sheet Example of Data Struc
A1: Time Series Data | K1: Cross Section Data | U1: Panel Data
A2: Baja Auto | B2: Year | C2: Current Ratio | D2: Gross Profit Margin | E2: EBITDA Margin | F2: EBIT Margin | G2: Net Profit Margin | H2: Return on Assets (ROA) | L2: 2022 | M2: 2022 | N2: 2022 | O2: 2022 | P2: 2022 | Q2: 2022 | R2: 2022 | U2: Company | V2: Year | W2: Company code | X2: CCC | Y2: NWC | Z2: FLCS | AA2: GRWTH | AB2: Size | AC2: ASTANG | AD2: CA/TA | AE2: CL/TA | AF2: LEV | AG2: CFLW_P/TA | AH2: CFLW_CFO/TA | AI2: PROF | AJ2: Age | AK2: B_Group
B3: 2020 | C3: 1.5554918 | D3: 29.781992 | E3: 16.722847 | F3: 15.89918 | G3: 17.046157 | H3: 19.237933 | K3: Company Name | L3: GRWT | M3: Size | N3: FA/TA | O3: NWC | P3: LEV | Q3: PRF (EBIT/TA) | R3: CFO/TA | U3: 3D Technopack Pvt. Ltd. | V3: 2011 | W3: 1 | X3: 70.468066 | Y3: -5.54 | Z3: 2 | AA3: 0 | AB3: 4.3110675 | AC3: 0.57098765 | AD3: 0.23604402 | AE3: 0.31038647 | AF3: 0.21484165 | AG3: -0.0856146 | AH3: 0.027777778 | AI3: -0.041062802 | AJ3: 25 | AK3: 0
B4: 2021 | C4: 2.5139646 | D4: 29.311873 | E4: 17.721769 | F4: 16.787126 | G4: 16.418214 | H4: 13.554638 | K4: 3D Technopack Pvt. Ltd. | L4: 0.20838339 | M4: 4.554929 | N4: 0.53101998 | O4: 9.97 | P4: 0.19148265 | Q4: -0.032071504 | R4: 0.13375394 | U4: 3D Technopack Pvt. Ltd. | V4: 2012 | W4: 1 | X4: 74.350217 | Y4: -12.17 | Z4: 2 | AA4: 0.048349688 | AB4: 4.3816516 | AC4: 0.73565087 | AD4: 0.2413405 | AE4: 0.39352257 | AF4: 0.18344379 | AG4: -0.11104164 | AH4: 0.053269976 | AI4: -0.061272977 | AJ4: 26 | AK4: 0
B5: 2022 | C5: 2.2108585 | D5: 26.595164 | E5: 15.825542 | F5: 15.013437 | G5: 15.142296 | H5: 14.29421 | K5: 3M India Ltd. | L5: 0.27183559 | M5: 8.1055943 | N5: 0.087773736 | O5: 1511.85 | P5: 0.0020585883 | Q5: 0.11334913 | R5: 0.10071085 | U5: 3D Technopack Pvt. Ltd. | V5: 2013 | W5: 1 | X5: 86.738234 | Y5: -9.9 | Z5: 3 | AA5: 0.23366236 | AB5: 4.3613136 | AC5: 0.65735069 | AD5: 0.32223073 | AE5: 0.4485707 | AF5: 0.10247575 | AG5: -0.053343543 | AH5: 0.074400204 | AI5: 0.0017866258 | AJ5: 27 | AK5: 0
B6: 2023 | C6: 1.8309384 | D6: 28.47525 | E6: 17.90214 | F6: 17.126794 | G6: 15.448726 | H6: 16.016416 | K6: A B B India Ltd. | L6: 0.19121449 | M6: 9.0377913 | N6: 0.097084194 | O6: 2631.55 | P6: 0.0022019757 | Q6: 0.086258507 | R6: 0.077264036 | U6: 3D Technopack Pvt. Ltd. | V6: 2014 | W6: 1 | X6: 89.064757 | Y6: -14.85 | Z6: 3 | AA6: -0.15257277 | AB6: 4.252914 | AC6: 0.63874271 | AD6: 0.33736311 | AE6: 0.54857062 | AF6: 0.070971412 | AG6: -0.16242355 | AH6: 0.063575594 | AI6: -0.10069691 | AJ6: 28 | AK6: 0
B7: 2024 | C7: 1.2977749 | D7: 28.96212 | E7: 19.638189 | F7: 18.855291 | G7: 16.736604 | H7: 19.008868 | K7: A B I-Showatech (India) Pvt. Ltd. | L7: 0.33976258 | M7: 6.670386 | N7: 0.31611513 | O7: 156.64 | P7: 0.1184354 | Q7: 0.05432991 | R7: 0.02444529 | U7: 3D Technopack Pvt. Ltd. | V7: 2015 | W7: 1 | X7: 78.027362 | Y7: -5.33 | Z7: 4 | AA7: 0.077649357 | AB7: 4.1191998 | AC7: 0.58088116 | AD7: 0.36709478 | AE7: 0.45374736 | AF7: 0.22516664 | AG7: -0.15395871 | AH7: 0.057063892 | AI7: -0.06828158 | AJ7: 29 | AK7: 0
B8: 2025 | C8: 1.6787162 | D8: 29.33969 | E8: 20.094037 | F8: 19.294022 | G8: 16.299479 | H8: 15.039906 | K8: A B Jewels Pvt. Ltd. | L8: 2.263656 | M8: 5.7472889 | N8: 0.011935916 | O8: 117.12 | P8: 0 | Q8: 0.1668156 | R8: 0.026456884 | U8: 3D Technopack Pvt. Ltd. | V8: 2016 | W8: 1 | X8: 54.512375 | Y8: -11.31 | Z8: 3 | AA8: 0.2244713 | AB8: 4.1526135 | AC8: 0.4822327 | AD8: 0.37201258 | AE8: 0.54984277 | AF8: 0.22515723 | AG8: -0.075628931 | AH8: 0.16996855 | AI8: -0.0047169811 | AJ8: 30 | AK8: 0
K9: A C C Ltd. | L9: 0.17166156 | M9: 9.962797 | N9: 0.31678342 | O9: 4252.97 | P9: 0.0047766311 | Q9: 0.11829949 | R9: 0.13342808 | U9: 3D Technopack Pvt. Ltd. | V9: 2017 | W9: 1 | X9: 46.350734 | Y9: -12.58 | Z9: 3 | AA9: -0.011349618 | AB9: 4.0780458 | AC9: 0.54192783 | AD9: 0.37963747 | AE9: 0.59274945 | AF9: 0.17499576 | AG9: -0.021514484 | AH9: 0.15432831 | AI9: 0.052854481 | AJ9: 31 | AK9: 0
K10: A C G Pharmapack Pvt. Ltd. | L10: 0.20660436 | M10: 6.3245023 | N10: 0.16298739 | O10: 127.28 | P10: 0.071996846 | Q10: 0.090435063 | R10: 0.06993621 | U10: 3D Technopack Pvt. Ltd. | V10: 2018 | W10: 1 | X10: 22.211493 | Y10: 29.42 | Z10: 2 | AA10: 0.15185925 | AB10: 4.8104756 | AC10: 0.33154166 | AD10: 0.53286098 | AE10: 0.29326492 | AF10: 0.081439857 | AG10: 0.011890219 | AH10: 0.037869533 | AI10: 0.044221842 | AJ10: 32 | AK10: 0
K11: A D F Foods Ltd. | L11: 0.27628465 | M11: 6.1208687 | N11: 0.1786232 | O11: 183.22 | P11: 0.00013179282 | Q11: 0.12498353 | R11: 0.083930062 | U11: 3D Technopack Pvt. Ltd. | V11: 2019 | W11: 1 | X11: 103.52815 | Y11: 26.64 | Z11: 1 | AA11: -0.030332575 | AB11: 4.9159582 | AC11: 0.51872481 | AD11: 0.44543789 | AE11: 0.25020154 | AF11: 0.20923415 | AG11: -0.022132649 | AH11: -0.019787468 | AI11: 0.0045437889 | AJ11: 33 | AK11: 0
K12: A G I Greenpac Ltd. | L12: 0.14167607 | M12: 8.1057271 | N12: 0.33758175 | O12: 631.57 | P12: 0.26287277 | Q12: 0.082812467 | R12: 0.054554399 | U12: 3D Technopack Pvt. Ltd. | V12: 2020 | W12: 1 | X12: 106.34594 | Y12: 18.8 | Z12: 3 | AA12: -0.038878338 | AB12: 4.7295978 | AC12: 0.5581457 | AD12: 0.39222958 | AE12: 0.22622517 | AF12: 0.19549669 | AG12: -0.073024283 | AH12: 0.14004415 | AI12: -0.03205298 | AJ12: 34 | AK12: 0
K13: A I A Engineering Ltd. | L13: 0.24596838 | M13: 8.7507622 | N13: 0.12123189 | O13: 3277.48 | P13: 0.00048768902 | Q13: 0.12016151 | R13: 0.0049908954 | U13: 3D Technopack Pvt. Ltd. | V13: 2021 | W13: 1 | X13: 121.86861 | Y13: 18.6 | Z13: 3 | AA13: -0.12925724 | AB13: 4.6849975 | AC13: 0.50946358 | AD13: 0.43809436 | AE13: 0.26636506 | AF13: 0.23063429 | AG13: -0.10165266 | AH13: 0.091219647 | AI13: -0.06518327 | AJ13: 35 | AK13: 0
K14: A I Champdany Inds. Ltd. | L14: -0.38173091 | M14: 5.7565647 | N14: 0.1809587 | O14: 141.31 | P14: 0.019920319 | Q14: -0.0031935749 | R14: -0.0030670967 | U14: 3D Technopack Pvt. Ltd. | V14: 2022 | W14: 1 | X14: 114.24005 | Y14: 9.97 | Z14: 3 | AA14: 0.20838339 | AB14: 4.554929 | AC14: 0.53101998 | AD14: 0.39768665 | AE14: 0.29284963 | AF14: 0.21524711 | AG14: -0.080967403 | AH14: 0.13375394 | AI14: -0.032071504 | AJ14: 36 | AK14: 0
K15: A I S Glass Solutions Ltd. | L15: 0.62960047 | M15: 4.9548407 | N15: 0.42252925 | O15: -53.43 | P15: 0.087551107 | Q15: -0.065698576 | R15: 0.10341181 | U15: 3M India Ltd. | V15: 2011 | W15: 2 | X15: 76.904642 | Y15: 270.26 | Z15: 2 | AA15: 0 | AB15: 6.6355265 | AC15: 0.21702027 | AD15: 0.6107683 | AE15: 0.25594738 | AF15: 0.035868081 | AG15: 0.12972639 | AH15: 0.069110388 | AI15: 0.19979519 | AJ15: 24 | AK15: 0
K16: A M C L Machinery Ltd. | L16: 0.16096866 | M16: 2.8207835 | N16: 0.21203097 | O16: -10.78 | P16: 0 | Q16: -0.19892793 | R16: 0.23942823 | U16: 3M India Ltd. | V16: 2012 | W16: 2 | X16: 83.818405 | Y16: 267.7 | Z16: 2 | AA16: 0.19138547 | AB16: 6.8419893 | AC16: 0.30956373 | AD16: 0.60708069 | AE16: 0.32118332 | AF16: 0.033577188 | AG16: 0.069172852 | AH16: 0.022310034 | AI16: 0.10957441 | AJ16: 25 | AK16: 0
K17: A M D Industries Ltd. | L17: 0.76364707 | M17: 5.6917436 | N17: 0.32390945 | O17: 48.56 | P17: 0.08839108 | Q17: 0.063020816 | R17: -0.043891906 | U17: 3M India Ltd. | V17: 2013 | W17: 2 | X17: 90.467588 | Y17: 221.15 | Z17: 2 | AA17: 0.12320303 | AB17: 7.2199714 | AC17: 0.21921768 | AD17: 0.65835559 | AE17: 0.49651286 | AF17: 0.023089026 | AG17: 0.038252406 | AH17: 0.046683011 | AI17: 0.062526986 | AJ17: 26 | AK17: 0
K18: A P L Apollo Tubes Ltd. | L18: 0.50839886 | M18: 8.1454887 | N18: 0.26113829 | O18: 193.93 | P18: 0.05024958 | Q18: 0.12248136 | R18: 0.04648775 | U18: 3M India Ltd. | V18: 2014 | W18: 2 | X18: 93.055259 | Y18: 256.81 | Z18: 3 | AA18: 0.10021241 | AB18: 7.2701459 | AC18: 0.2911203 | AD18: 0.66642306 | AE18: 0.48768061 | AF18: 0.025508784 | AG18: 0.02992149 | AH18: 0.08379966 | AI18: 0.053363123 | AJ18: 27 | AK18: 0
K19: A P L Metals Ltd. | L19: 0.13348488 | M19: 5.3862367 | N19: 0.10289404 | O19: 52.61 | P19: 0.18509021 | Q19: 0.094605733 | R19: -0.050233538 | U19: 3M India Ltd. | V19: 2015 | W19: 2 | X19: 91.807156 | Y19: 400.67 | Z19: 3 | AA19: 0.06039305 | AB19: 7.3353797 | AC19: 0.25283481 | AD19: 0.49781887 | AE19: 0.23655949 | AF19: 0.23676163 | AG19: 0.070643775 | AH19: 0.1156487 | AI19: 0.10835871 | AJ19: 28 | AK19: 0
K20: A P M Industries Ltd. | L20: 0.33953174 | M20: 5.5068345 | N20: 0.65133742 | O20: 32.88 | P20: 0.062061128 | Q20: 0.10703414 | R20: 0.060518732 | U20: 3M India Ltd. | V20: 2016 | W20: 2 | X20: 79.434809 | Y20: 601.44 | Z20: 4 | AA20: 0.15346311 | AB20: 7.3128803 | AC20: 0.23288585 | AD20: 0.71205543 | AE20: 0.31095906 | AF20: 0.0300969 | AG20: 0.12988416 | AH20: 0.17399916 | AI20: 0.2036359 | AJ20: 29 | AK20: 0
... K46: Advanced Enzyme Technologies Ltd. | L46: -0.037674615 | M46: 6.2751762 | N46: 0.24854109 | O46: 140.36 | P46: 0.0017883363 | Q46: 0.1361771 | R46: 0.069858063 | U46: Adani Wilmar Ltd. | V46: 2018 | W46: 4 | X46: 88.321296 | Y46: 80.66 | Z46: 3 | AA46: 0.088470822 | AB46: 6.4128358 | AC46: 0.25916144 | AD46: 0.32864735 | AE46: 0.19633542 | AF46: 0 | AG46: 0.083822709 | AH46: 0.11497326 | AI46: 0.12934287 | AJ46: 27 | AK46: 0
K47: Advik Hi-Tech Pvt. Ltd. | L47: 0.1171151 | M47: 6.233685 | N47: 0.30753684 | O47: 153.09 | P47: 0.064537017 | Q47: 0.13978769 | R47: 0.085964327
K48: Agarwal Industrial Corpn. Ltd. | L48: 0.68643753 | M48: 6.0710148 | N48: 0.16718231 | O48: 176.89 | P48: 0.079446805 | Q48: 0.14753417 | R48: 0.067071481
K49: Agrasen Engineering Inds. Pvt. Ltd. | L49: 0.76693011 | M49: 5.5197795 | N49: 0.45804952 | O49: 31.71 | P49: 0 | Q49: 0.22682106 | R49: 0.075046077
K50: Agribiotech Industries Ltd. | L50: 0.15521731 | M50: 4.735672 | N50: 0.22898016 | O50: 15.48 | P50: 0.12883974 | Q50: 0.07416184 | R50: 0.053888011
K51: Agro Tech Foods Ltd. | L51: -0.015567421 | M51: 6.4531052 | N51: 0.45910473 | O51: 131.22 | P51: 0.015803488 | Q51: 0.05993666 | R51: -0.045440938
K52: Ahlcon Parenterals (India) Ltd. | L52: 0.32769045 | M52: 5.6579479 | N52: 0.67881072 | O52: -62.14 | P52: 0.88288666 | Q52: 0.020379676 | R52: 0.039921831
K53: Air Control & Chemical Engg. Co. Ltd. | L53: 0.44031794 | M53: 4.8147015 | N53: 0.42616171 | O53: 24.4 | P53: 0.067147839 | Q53: 0.063093018 | R53: -0.018895467
K54: Ajanta Pharma Ltd. | L54: 0.15524592 | M54: 8.2990621 | N54: 0.36912266 | O54: 1587.31 | P54: 0.004062088 | Q54: 0.23263352 | R54: 0.13490709
K55: Ajanta Soya Ltd. | L55: 0.44421301 | M55: 5.5802957 | N55: 0.15229116 | O55: 77.84 | P55: 0 | Q55: 0.20388459 | R55: 0.09526683
K56: Akar Auto Inds. Ltd. | L56: 0.42783175 | M56: 5.0805344 | N56: 0.23417879 | O56: 24.45 | P56: 0.1564093 | Q56: 0.095486759 | R56: 0.096232749
K57: Aksh Optifibre Ltd. | L57: 0.216866 | M57: 6.2873008 | N57: 0.25032546 | O57: -43.91 | P57: 0.028231356 | Q57: 0.081346476 | R57: 0.10511438
K58: Aksharchem (India) Ltd. | L58: 0.5299646 | M58: 6.0066487 | N58: 0.56936373 | O58: 66.93 | P58: 0.055402344 | Q58: 0.052964641 | R58: 0.01063725
K59: Akums Drugs & Pharmaceuticals Ltd. | L59: 0.38763374 | M59: 7.5075529 | N59: 0.12816797 | O59: 19.32 | P59: 0.0091615205 | Q59: -0.18120489 | R59: 0.12532455
